Ignoring exception in command 따라해:
Traceback (most recent call last):
  File "/usr/local/lib/python3.6/dist-packages/discord/ext/commands/core.py", line 85, in wrapped
    ret = await coro(*args, **kwargs)
  File "Miku.py", line 69, in 따라해
    await ctx.send(msg)
  File "/usr/local/lib/python3.6/dist-packages/discord/abc.py", line 1067, in send
    message_reference=reference)
  File "/usr/local/lib/python3.6/dist-packages/discord/http.py", line 254, in request
    raise HTTPException(r, data)
discord.errors.HTTPException: 400 Bad Request (error code: 50006): Cannot send an empty message

The above exception was the direct cause of the following exception:

Traceback (most recent call last):
  File "/usr/local/lib/python3.6/dist-packages/discord/ext/commands/bot.py", line 939, in invoke
    await ctx.command.invoke(ctx)
  File "/usr/local/lib/python3.6/dist-packages/discord/ext/commands/core.py", line 863, in invoke
    await injected(*ctx.args, **ctx.kwargs)
  File "/usr/local/lib/python3.6/dist-packages/discord/ext/commands/core.py", line 94, in wrapped
    raise CommandInvokeError(exc) from exc
discord.ext.commands.errors.CommandInvokeError: Command raised an exception: HTTPException: 400 Bad Request (error code: 50006): Cannot send an empty message
Ignoring exception in command 신음:
Traceback (most recent call last):
  File "/usr/local/lib/python3.6/dist-packages/discord/ext/commands/core.py", line 85, in wrapped
    ret = await coro(*args, **kwargs)
  File "Miku.py", line 350, in 신음
    await ctx.sent("무야호~무야호~")
AttributeError: 'Context' object has no attribute 'sent'

The above exception was the direct cause of the following exception:

Traceback (most recent call last):
  File "/usr/local/lib/python3.6/dist-packages/discord/ext/commands/bot.py", line 939, in invoke
    await ctx.command.invoke(ctx)
  File "/usr/local/lib/python3.6/dist-packages/discord/ext/commands/core.py", line 863, in invoke
    await injected(*ctx.args, **ctx.kwargs)
  File "/usr/local/lib/python3.6/dist-packages/discord/ext/commands/core.py", line 94, in wrapped
    raise CommandInvokeError(exc) from exc
discord.ext.commands.errors.CommandInvokeError: Command raised an exception: AttributeError: 'Context' object has no attribute 'sent'
봇 준비 완료!
미쿠봇
---------------
Fatal read error on socket transport
protocol: <asyncio.sslproto.SSLProtocol object at 0x733f08d0>
transport: <_SelectorSocketTransport fd=9 read=polling write=<idle, bufsize=0>>
Traceback (most recent call last):
  File "/usr/lib/python3.6/asyncio/selector_events.py", line 714, in _read_ready
    data = self._sock.recv(self.max_size)
OSError: [Errno 113] No route to host
